Workbook

Sheet Repo rate
A1: RBI Repo rate
A4: 23-06-2026 | B4: 5.25

Sheet Punjab National Bank
A1: Bank | B1: Punjab National Bank
A2: Interest rate link | B2: https://pnb.bank.in/Retail-Advances-interst-rate-on-advances-linked-to-mclr.html
A3: Credit score range given | B3: Yes
A4: Interest rates as per score | B4: Yes
A5: Gender split | B5: No
A6: Occupation split | B6: No
A7: Rate types | B7: Floating & Fixed
A8: Rate base | B8: Repo + Mark-up + BSP
A9: Special Govt. Employees | B9: Yes
A10: Loan Type - Term Loan | B10: Yes
A11: Loan Type - Overdraft | B11: Yes
A12: Top up | B12: Yes
A13: Rate varies by insurance | B13: No
A14: Updated as on | B14: 46249
A15: Rate | B15: Floating rate | H15: Fixed Rate
B16: RLLR | D16: BSP | E16: RLLR + BSP | G16: ROI
B17: Repo Rate | C17: Markup | D17: Business Strategic Premium | E17: Rate base | F17: Discount / Extra | G17: Final rate | H17: Tenure upto 10 years | I17: Tenure above 10 years
A19: Scheme | B19: Housing Loan For Public
A20: Loan Type | B20: Term Loan
A22: Condition
A23: Loan amount | B23: > 30 lakhs
A25: 800+ | B25: ='Repo rate'!$B$4 -> 5.25 | C25: 2.75 | D25: 0.1 | E25: =B25+C25+D25 -> 8.1 | F25: -0.85 | G25: =E25+F25 -> 7.25 | H25: 8.25 | I25: 8.75 | K25: =I25-G25 -> 1.5
A26: PNB Pride | B26: ='Repo rate'!$B$4 -> 5.25 | C26: 2.75 | D26: 0.1 | E26: =B26+C26+D26 -> 8.1 | F26: -0.8 | G26: =E26+F26 -> 7.3 | H26: 8.3 | I26: 8.8 | K26: =I26-G26 -> 1.5
A27: 750 - 799 | B27: ='Repo rate'!$B$4 -> 5.25 | C27: 2.75 | D27: 0.1 | E27: =B27+C27+D27 -> 8.1 | F27: -0.8 | G27: =E27+F27 -> 7.3 | H27: 8.3 | I27: 8.8 | K27: =I27-G27 -> 1.5
A28: 700 - 749 | B28: ='Repo rate'!$B$4 -> 5.25 | C28: 2.75 | D28: 0.1 | E28: =B28+C28+D28 -> 8.1 | F28: -0.25 | G28: =E28+F28 -> 7.85 | H28: 8.85 | I28: 9.35 | K28: =I28-G28 -> 1.5
A29: 600 - 699 | B29: ='Repo rate'!$B$4 -> 5.25 | C29: 2.75 | D29: 0.1 | E29: =B29+C29+D29 -> 8.1 | F29: 0.95 | G29: =E29+F29 -> 9.05 | H29: 10.05 | I29: 10.55 | K29: =I29-G29 -> 1.5
A31: Condition
A32: Loan amount | B32: < 30 lakhs
A34: PNB Pride | B34: ='Repo rate'!$B$4 -> 5.25 | C34: 2.75 | D34: 0.1 | E34: =B34+C34+D34 -> 8.1 | F34: -0.7 | G34: =E34+F34 -> 7.4 | H34: 8.4 | I34: 8.9 | K34: =I34-G34 -> 1.5
A35: 750+ | B35: ='Repo rate'!$B$4 -> 5.25 | C35: 2.75 | D35: 0.1 | E35: =B35+C35+D35 -> 8.1 | F35: -0.7 | G35: =E35+F35 -> 7.4 | H35: 8.4 | I35: 8.9 | K35: =I35-G35 -> 1.5
A36: 700 - 749 | B36: ='Repo rate'!$B$4 -> 5.25 | C36: 2.75 | D36: 0.1 | E36: =B36+C36+D36 -> 8.1 | F36: -0.15 | G36: =E36+F36 -> 7.95 | H36: 8.95 | I36: 9.45 | K36: =I36-G36 -> 1.5
A37: 600 - 699 | B37: ='Repo rate'!$B$4 -> 5.25 | C37: 2.75 | D37: 0.1 | E37: =B37+C37+D37 -> 8.1 | F37: 1.05 | G37: =E37+F37 -> 9.15 | H37: 10.15 | I37: 10.65 | K37: =I37-G37 -> 1.5
A39: Scheme | B39: PNB Max-Saver
A40: Loan type | B40: Overdraft
A42: Condition
A43: Loan amount | B43: > 30 lakhs
A45: 800+ | B45: ='Repo rate'!$B$4 -> 5.25 | C45: 2.75 | D45: 0.1 | E45: =B45+C45+D45 -> 8.1 | F45: -0.7 | G45: =E45+F45 -> 7.4 | H45: 8.4 | I45: 8.9 | K45: =I45-G45 -> 1.5
A46: PNB Pride | B46: ='Repo rate'!$B$4 -> 5.25 | C46: 2.75 | D46: 0.1 | E46: =B46+C46+D46 -> 8.1 | F46: -0.65 | G46: =E46+F46 -> 7.45 | H46: 8.45 | I46: 8.95 | K46: =I46-G46 -> 1.5
A47: 750 - 799 | B47: ='Repo rate'!$B$4 -> 5.25 | C47: 2.75 | D47: 0.1 | E47: =B47+C47+D47 -> 8.1 | F47: -0.65 | G47: =E47+F47 -> 7.45 | H47: 8.45 | I47: 8.95 | K47: =I47-G47 -> 1.5
A48: 700 - 749 | B48: ='Repo rate'!$B$4 -> 5.25 | C48: 2.75 | D48: 0.1 | E48: =B48+C48+D48 -> 8.1 | F48: -0.1 | G48: =E48+F48 -> 8 | H48: 9 | I48: 9.5 | K48: =I48-G48 -> 1.5
...

Sheet Central Bank of India
A1: Bank | B1: Central Bank of India
A2: Interest rate link | B2: https://centralbank.bank.in/en/retail-scheme-interest
A3: Credit score range given | B3: No
A4: Interest rates as per score | B4: No
A5: Gender split | B5: No
A6: Occupation split | B6: No
A7: Rate types | B7: Floating
A8: Rate base | B8: Repo + Mark-up
A9: Special Govt. Employees | B9: No
A10: Loan Type - Term Loan | B10: Yes
A11: Loan Type - Overdraft | B11: Yes
A12: Rate varies by insurance | B12: No
A13: Updaetd as on | B13: 46217
A14: Rate | B14: Floating rate
B15: RBLR | D15: RBLR | F15: ROI
B16: Repo Rate | C16: Mark-up | D16: Rate base | E16: Discount / Extra | F16: Final rate
A18: Scheme | B18: Cent Home loan
A19: Loan type | B19: Term Loan
A21: 800+ | B21: ='Repo rate'!$B$4 -> 5.25 | C21: 3 | D21: =B21+C21 -> 8.25 | E21: -1.05 | F21: =D21+E21 -> 7.2
A22: 775 - 799 | B22: ='Repo rate'!$B$4 -> 5.25 | C22: 3 | D22: =B22+C22 -> 8.25 | E22: -0.95 | F22: =D22+E22 -> 7.3
A23: 750 - 774 | B23: ='Repo rate'!$B$4 -> 5.25 | C23: 3 | D23: =B23+C23 -> 8.25 | E23: -0.6 | F23: =D23+E23 -> 7.65
A24: 725 - 749 | B24: ='Repo rate'!$B$4 -> 5.25 | C24: 3 | D24: =B24+C24 -> 8.25 | E24: 0.2 | F24: =D24+E24 -> 8.45
A25: 700 - 724 | B25: ='Repo rate'!$B$4 -> 5.25 | C25: 3 | D25: =B25+C25 -> 8.25 | E25: 0.5 | F25: =D25+E25 -> 8.75
A27: Scheme | B27: Cent Home Double Plus Scheme
A28: Loan type | B28: Overdraft
A30: 800+ | B30: ='Repo rate'!$B$4 -> 5.25 | C30: 3 | D30: =B30+C30 -> 8.25 | E30: =0.1 -> 0.1 | F30: =D30+E30 -> 8.35
A31: 775 - 799 | B31: ='Repo rate'!$B$4 -> 5.25 | C31: 3 | D31: =B31+C31 -> 8.25 | E31: 0.2 | F31: =D31+E31 -> 8.45
A32: 750 - 774 | B32: ='Repo rate'!$B$4 -> 5.25 | C32: 3 | D32: =B32+C32 -> 8.25 | E32: 0.3 | F32: =D32+E32 -> 8.55
A33: 725 - 749 | B33: ='Repo rate'!$B$4 -> 5.25 | C33: 3 | D33: =B33+C33 -> 8.25 | E33: 0.5 | F33: =D33+E33 -> 8.75
A34: 700 - 724 | B34: ='Repo rate'!$B$4 -> 5.25 | C34: 3 | D34: =B34+C34 -> 8.25 | E34: =0.9 -> 0.9 | F34: =D34+E34 -> 9.15
A36: Scheme | B36: CENT TOP UP SCHEME
A37: Loan type | B37: Term Loan
A39: 800+ | B39: ='Repo rate'!$B$4 -> 5.25 | C39: 3 | D39: =B39+C39 -> 8.25 | E39: -0.3 | F39: =D39+E39 -> 7.95
A40: 775 - 799 | B40: ='Repo rate'!$B$4 -> 5.25 | C40: 3 | D40: =B40+C40 -> 8.25 | E40: -0.2 | F40: =D40+E40 -> 8.05
A41: 750 - 774 | B41: ='Repo rate'!$B$4 -> 5.25 | C41: 3 | D41: =B41+C41 -> 8.25 | E41: 0.3 | F41: =D41+E41 -> 8.55
A42: 725 - 749 | B42: ='Repo rate'!$B$4 -> 5.25 | C42: 3 | D42: =B42+C42 -> 8.25 | E42: 0.8 | F42: =D42+E42 -> 9.05
A43: 700 - 724 | B43: ='Repo rate'!$B$4 -> 5.25 | C43: 3 | D43: =B43+C43 -> 8.25 | E43: 1.05 | F43: =D43+E43 -> 9.3

Sheet Bank of India
A1: Bank | B1: Bank of India
A2: Interest rate link | B2: https://bankofindia.bank.in/interest-rate/retail-advances
A3: Credit score range given | B3: Yes
A4: Interest rates as per score | B4: Yes
A5: Gender split | B5: No
A6: Occupation split | B6: Yes
A7: Rate types | B7: Floating & Fixed
A8: Rate base | B8: Repo + Mark-up
A9: Special Govt. Employees | B9: Yes
A10: Loan Type - Term Loan | B10: Yes
A11: Loan Type - Overdraft | B11: Yes
A12: Top up | B12: Yes
A13: Rate varies by insurance | B13: Yes
A14: Updaetd as on | B14: 46217
A21: Occupation | B21: Salaried
A22: Rate | D22: Floating rate
B23: RBLR | D23: RBLR | G23: ROI | H23: Remarks
B24: Repo Rate | C24: Markup | D24: Rate base | E24: Credit Risk Premium (CRP) | F24: Business Strategy Discount (BSD) | G24: Final rate
A26: Scheme | B26: Star Home Loan/Star Smart Home Loan/ Star Diamond Home Loan
A27: Loan type | B27: Term loan & Overdraft
A29: 840 + | B29: ='Repo rate'!$B$4 -> 5.25 | C29: 2.85 | D29: =B29+C29 -> 8.1 | E29: 0 | F29: -1 | G29: =D29+E29+F29 -> 7.1
A30: 825 - 839 | B30: ='Repo rate'!$B$4 -> 5.25 | C30: 2.85 | D30: =B30+C30 -> 8.1 | E30: 0 | F30: -0.85 | G30: =D30+E30+F30 -> 7.25
A31: 800 - 824 | B31: ='Repo rate'!$B$4 -> 5.25 | C31: 2.85 | D31: =B31+C31 -> 8.1 | E31: 0 | F31: -0.85 | G31: =D31+E31+F31 -> 7.25
A32: 760 - 799 | B32: ='Repo rate'!$B$4 -> 5.25 | C32: 2.85 | D32: =B32+C32 -> 8.1 | E32: 0 | F32: -0.7 | G32: =D32+E32+F32 -> 7.4
A33: 725 - 759 | B33: ='Repo rate'!$B$4 -> 5.25 | C33: 2.85 | D33: =B33+C33 -> 8.1 | E33: 0.1 | F33: -0.3 | G33: =D33+E33+F33 -> 7.9
A34: 700 - 724 | B34: ='Repo rate'!$B$4 -> 5.25 | C34: 2.85 | D34: =B34+C34 -> 8.1 | E34: 0.3 | F34: 0 | G34: =D34+E34+F34 -> 8.4
A35: <700 | B35: ='Repo rate'!$B$4 -> 5.25 | C35: 2.85 | D35: =B35+C35 -> 8.1 | E35: 1.9 | F35: 0 | G35: =D35+E35+F35 -> 10 | H35: Only for review
A36: -1 & 0 | B36: ='Repo rate'!$B$4 -> 5.25 | C36: 2.85 | D36: =B36+C36 -> 8.1 | E36: 0.3 | F36: -0.5 | G36: =D36+E36+F36 -> 7.9
A38: Scheme | B38: Star Top Up Loan
A39: Loan type | B39: Term loan & Overdraft
A41: 840 + | B41: ='Repo rate'!$B$4 -> 5.25 | C41: 2.85 | D41: =B41+C41 -> 8.1 | E41: 0 | F41: -0.5 | G41: =D41+E41+F41 -> 7.6 | I41: =G41-G29 -> 0.5
A42: 825 - 839 | B42: ='Repo rate'!$B$4 -> 5.25 | C42: 2.85 | D42: =B42+C42 -> 8.1 | E42: 0 | F42: -0.35 | G42: =D42+E42+F42 -> 7.75 | I42: =G42-G30 -> 0.5
A43: 800 - 824 | B43: ='Repo rate'!$B$4 -> 5.25 | C43: 2.85 | D43: =B43+C43 -> 8.1 | E43: 0 | F43: -0.35 | G43: =D43+E43+F43 -> 7.75 | I43: =G43-G31 -> 0.5
A44: 760 - 799 | B44: ='Repo rate'!$B$4 -> 5.25 | C44: 2.85 | D44: =B44+C44 -> 8.1 | E44: 0 | F44: -0.2 | G44: =D44+E44+F44 -> 7.9 | I44: =G44-G32 -> 0.5
A45: 725 - 759 | B45: ='Repo rate'!$B$4 -> 5.25 | C45: 2.85 | D45: =B45+C45 -> 8.1 | E45: 0.1 | F45: 0.2 | G45: =D45+E45+F45 -> 8.4 | I45: =G45-G33 -> 0.5
A46: 700 - 724 | B46: ='Repo rate'!$B$4 -> 5.25 | C46: 2.85 | D46: =B46+C46 -> 8.1 | E46: 0.3 | F46: 0.5 | G46: =D46+E46+F46 -> 8.9 | I46: =G46-G34 -> 0.5
A47: <700 | B47: ='Repo rate'!$B$4 -> 5.25 | C47: 2.85 | D47: =B47+C47 -> 8.1 | E47: 1.9 | F47: 0.5 | G47: =D47+E47+F47 -> 10.5 | H47: Only for review | I47: =G47-G35 -> 0.5
A48: -1 & 0 | B48: ='Repo rate'!$B$4 -> 5.25 | C48: 2.85 | D48: =B48+C48 -> 8.1 | E48: 0.3 | F48: 0 | G48: =D48+E48+F48 -> 8.4 | I48: =G48-G36 -> 0.5
A52: Occupation | B52: Self-Employed
A55: Scheme | B55: Star Home Loan/Star Smart Home Loan/ Star Diamond Home Loan
...

Sheet Union Bank of India
A1: Bank | B1: Union Bank of India
A2: Interest rate link | B2: https://www.unionbankofindia.bank.in/en/details/home-loan
A3: Credit score range given | B3: Yes
A4: Interest rates as per score | B4: Yes
A5: Gender split | B5: Yes
A6: Occupation split | B6: Yes
A7: Rate types | B7: Floating & Fixed
A8: Rate base | B8: Repo + Mark-up
A9: Special Govt. Employees | B9: Yes
A10: Loan Type - Term Loan | B10: Yes
A11: Loan Type - Overdraft | B11: Yes
A12: Top up | B12: No
A13: Rate varies by insurance | B13: Yes
A14: Updated as on | B14: 46227
A17: Scheme | B17: UNION HOME
A18: Loan type | B18: Term loan | D18: Floating rate
D19: External Benchmark Lending Rate | G19: Remarks
B20: Repo Rate | C20: Markup | D20: Rate base | E20: Discount | F20: Final rate
A21: Occupation | B21: Salaried
A22: 825+ | B22: ='Repo rate'!$B$4 -> 5.25 | C22: 2.75 | D22: =B22+C22 -> 8 | E22: -0.85 | F22: =D22+E22 -> 7.15
A23: 800 - 824 | B23: ='Repo rate'!$B$4 -> 5.25 | C23: 2.75 | D23: =B23+C23 -> 8 | E23: -0.8 | F23: =D23+E23 -> 7.2
A24: 750 - 799 | B24: ='Repo rate'!$B$4 -> 5.25 | C24: 2.75 | D24: =B24+C24 -> 8 | E24: -0.65 | F24: =D24+E24 -> 7.35
A25: 700 - 749 | B25: ='Repo rate'!$B$4 -> 5.25 | C25: 2.75 | D25: =B25+C25 -> 8 | E25: -0.25 | F25: =D25+E25 -> 7.75 | G25: 0.05 lesser for Female borrower = 7.70
A26: 680 - 699 | B26: ='Repo rate'!$B$4 -> 5.25 | C26: 2.75 | D26: =B26+C26 -> 8 | E26: 0 | F26: =D26+E26 -> 8 | G26: 0.05 lesser for Female borrower = 7.95
A27: 650 - 679 | B27: ='Repo rate'!$B$4 -> 5.25 | C27: 2.75 | D27: =B27+C27 -> 8 | E27: 0.85 | F27: =D27+E27 -> 8.85
A28: 600 - 649 | B28: ='Repo rate'!$B$4 -> 5.25 | C28: 2.75 | D28: =B28+C28 -> 8 | E28: 1.35 | F28: =D28+E28 -> 9.35
A29: -1 & 1 - 5 | B29: ='Repo rate'!$B$4 -> 5.25 | C29: 2.75 | D29: =B29+C29 -> 8 | E29: -0.6 | F29: =D29+E29 -> 7.4
A30: 750+ | B30: ='Repo rate'!$B$4 -> 5.25 | C30: 2.75 | D30: =B30+C30 -> 8 | E30: -0.85 | F30: =D30+E30 -> 7.15 | G30: Government / PSU Employees Only
A32: Occupation | B32: Self-Employed
A33: 825+ | B33: ='Repo rate'!$B$4 -> 5.25 | C33: 2.75 | D33: =B33+C33 -> 8 | E33: -0.85 | F33: =D33+E33 -> 7.15
A34: 800 - 824 | B34: ='Repo rate'!$B$4 -> 5.25 | C34: 2.75 | D34: =B34+C34 -> 8 | E34: -0.8 | F34: =D34+E34 -> 7.2
A35: 750 - 799 | B35: ='Repo rate'!$B$4 -> 5.25 | C35: 2.75 | D35: =B35+C35 -> 8 | E35: -0.6 | F35: =D35+E35 -> 7.4
A36: 700 - 749 | B36: ='Repo rate'!$B$4 -> 5.25 | C36: 2.75 | D36: =B36+C36 -> 8 | E36: -0.15 | F36: =D36+E36 -> 7.85 | G36: 0.05 lesser for Female borrower = 7.80
A37: 680 - 699 | B37: ='Repo rate'!$B$4 -> 5.25 | C37: 2.75 | D37: =B37+C37 -> 8 | E37: 0.1 | F37: =D37+E37 -> 8.1 | G37: 0.05 lesser for Female borrower = 8.05
A38: 650 - 679 | B38: ='Repo rate'!$B$4 -> 5.25 | C38: 2.75 | D38: =B38+C38 -> 8 | E38: 0.85 | F38: =D38+E38 -> 8.85
A39: 600 - 649 | B39: ='Repo rate'!$B$4 -> 5.25 | C39: 2.75 | D39: =B39+C39 -> 8 | E39: 1.35 | F39: =D39+E39 -> 9.35
A40: -1 & 1 - 5 | B40: ='Repo rate'!$B$4 -> 5.25 | C40: 2.75 | D40: =B40+C40 -> 8 | E40: -0.5 | F40: =D40+E40 -> 7.5
A43: Scheme | B43: UNION HOME-SMART SAVE SCHEME
A44: Loan type | B44: Overdraft
A46: Occupation | B46: Salaried
...

Sheet Bank of Baroda
A1: Bank | B1: Bank of Baroda
A2: Interest rate link | B2: https://bankofbaroda.bank.in/loans/home-loan/baroda-home-loan
A3: Credit score range given | B3: No | C3: But from internal executive
A4: Interest rates as per score | B4: No | C4: But from internal executive
A5: Gender split | B5: No
A6: Occupation split | B6: Yes
A7: Rate types | B7: Floating & Fixed
A8: Rate base | B8: Repo + Mark-up
A9: Special Govt. Employees | B9: No
A10: Loan Type - Term Loan | B10: Yes
A11: Loan Type - Overdraft | B11: Yes
A12: Top up | B12: No
A13: Rate varies by insurance | B13: Yes
A14: Updated as on | B14: 46217
A17: Scheme | B17: Baroda Home Loan, Baroda Home Improvement Loan
A18: Loan type | B18: Term loan
D19: Floating rate
D20: Baroda Repo Linked Lending Rate
B21: Repo Rate | C21: Markup | D21: Rate base | E21: Discount | F21: Final rate
A22: Occupation | B22: Salaried & Self-Employed
A23: 825+ | B23: ='Repo rate'!$B$4 -> 5.25 | C23: 2.65 | D23: =B23+C23 -> 7.9 | E23: -0.7 | F23: =D23+E23 -> 7.2
A24: 800 - 824 | B24: ='Repo rate'!$B$4 -> 5.25 | C24: 2.65 | D24: =B24+C24 -> 7.9 | E24: -0.6 | F24: =D24+E24 -> 7.3
A25: 751 - 799 | B25: ='Repo rate'!$B$4 -> 5.25 | C25: 2.65 | D25: =B25+C25 -> 7.9 | E25: -0.5 | F25: =D25+E25 -> 7.4
A26: 726 - 750 | B26: ='Repo rate'!$B$4 -> 5.25 | C26: 2.65 | D26: =B26+C26 -> 7.9 | E26: -0.25 | F26: =D26+E26 -> 7.65
A27: 701 - 725 | B27: ='Repo rate'!$B$4 -> 5.25 | C27: 2.65 | D27: =B27+C27 -> 7.9 | E27: -0.2 | F27: =D27+E27 -> 7.7
A28: 676 - 700 | B28: ='Repo rate'!$B$4 -> 5.25 | C28: 2.65 | D28: =B28+C28 -> 7.9 | E28: 0 | F28: =D28+E28 -> 7.9
A29: 650 - 675 | B29: ='Repo rate'!$B$4 -> 5.25 | C29: 2.65 | D29: =B29+C29 -> 7.9 | E29: 0.4 | F29: =D29+E29 -> 8.3
A30: 625 - 649 | B30: ='Repo rate'!$B$4 -> 5.25 | C30: 2.65 | D30: =B30+C30 -> 7.9 | E30: 0.6 | F30: =D30+E30 -> 8.5
A31: 600 - 624 | B31: ='Repo rate'!$B$4 -> 5.25 | C31: 2.65 | D31: =B31+C31 -> 7.9 | E31: 1.05 | F31: =D31+E31 -> 8.95
A32: -1 | B32: ='Repo rate'!$B$4 -> 5.25 | C32: 2.65 | D32: =B32+C32 -> 7.9 | E32: -0.15 | F32: =D32+E32 -> 7.75
A34: Risk Premium of 0.05% will be levied for customers not obtaining credit insurance cover
A36: Scheme | B36: Baroda Home Loan, Baroda Home Improvement Loan
A37: Loan type | B37: Term loan
A38: Occupation | B38: Salaried
D39: Fixed rate
A40: 825+ | B40: ='Repo rate'!$B$4 -> 5.25 | C40: 2.65 | D40: =B40+C40 -> 7.9 | E40: 1 | F40: =D40+E40 -> 8.9
A41: 800 - 824 | B41: ='Repo rate'!$B$4 -> 5.25 | C41: 2.65 | D41: =B41+C41 -> 7.9 | E41: 1.1 | F41: =D41+E41 -> 9
A42: 751 - 799 | B42: ='Repo rate'!$B$4 -> 5.25 | C42: 2.65 | D42: =B42+C42 -> 7.9 | E42: 1.25 | F42: =D42+E42 -> 9.15
A43: 726 - 750 | B43: ='Repo rate'!$B$4 -> 5.25 | C43: 2.65 | D43: =B43+C43 -> 7.9 | E43: 1.4 | F43: =D43+E43 -> 9.3
A44: 701 - 725 | B44: ='Repo rate'!$B$4 -> 5.25 | C44: 2.65 | D44: =B44+C44 -> 7.9 | E44: 1.5 | F44: =D44+E44 -> 9.4
...

Sheet Canara bank
A1: Bank | B1: Canara bank
A2: Interest rate link | B2: https://www.canarabank.bank.in/pages/rates-of-interest-for-retail-lending-schemes-linked-to-rllr
A3: Credit score range given | B3: Yes | C3: But from internal circular - https://www.scribd.com/document/866685005/Retail-Rate-of-Interest-12042025
A4: Interest rates as per score | B4: Yes
A5: Gender split | B5: Yes
A6: Occupation split | B6: Yes
A7: Rate types | B7: Floating & Fixed
A8: Rate base | B8: Repo + Mark-up
A9: Special Govt. Employees | B9: Yes
A10: Loan Type - Term Loan | B10: Yes
A11: Loan Type - Overdraft | B11: No
A12: Top up | B12: No
A13: Rate varies by insurance | B13: No
A14: Updated as on | B14: 46217
A15: Scheme | B15: HOUSING LOAN
A16: Loan type | B16: Term loan
E18: Floating rate
E19: Repo Linked Lending Rate | H19: ROI
B20: Canara Bank Internal Grouping | C20: Repo Rate | D20: Markup | E20: Rate base | F20: Credit Risk Premium | G20: Discount | H20: Final rate
A21: Condition | B21: Loan amount upto Rs. 50 lakhs
A22: 800+ | B22: CRG-prime | C22: ='Repo rate'!$B$4 -> 5.25 | D22: 2.75 | E22: =C22+D22 -> 8 | F22: 0.05 | G22: -0.75 | H22: =E22+F22+G22 -> 7.3
A23: 750 - 799 | B23: CRG-1 | C23: ='Repo rate'!$B$4 -> 5.25 | D23: 2.75 | E23: =C23+D23 -> 8 | F23: 0.05 | G23: -0.75 | H23: =E23+F23+G23 -> 7.3
A24: 700 - 749 | B24: CRG-2 | C24: ='Repo rate'!$B$4 -> 5.25 | D24: 2.75 | E24: =C24+D24 -> 8 | F24: 0.1 | G24: -0.4 | H24: =E24+F24+G24 -> 7.7
A25: 650 - 699 | B25: CRG-3 | C25: ='Repo rate'!$B$4 -> 5.25 | D25: 2.75 | E25: =C25+D25 -> 8 | F25: 0.5 | G25: 0 | H25: =E25+F25+G25 -> 8.5
A26: < 650 | B26: CRG-4 | C26: ='Repo rate'!$B$4 -> 5.25 | D26: 2.75 | E26: =C26+D26 -> 8 | F26: 2 | G26: 0 | H26: =E26+F26+G26 -> 10
A28: Condition | B28: Loan amount above Rs. 50 lakhs - 100 lakhs
A29: 800+ | B29: CRG-prime | C29: ='Repo rate'!$B$4 -> 5.25 | D29: 2.75 | E29: =C29+D29 -> 8 | F29: 0.05 | G29: -0.8 | H29: =E29+F29+G29 -> 7.25
A30: 750 - 799 | B30: CRG-1 | C30: ='Repo rate'!$B$4 -> 5.25 | D30: 2.75 | E30: =C30+D30 -> 8 | F30: 0.05 | G30: -0.8 | H30: =E30+F30+G30 -> 7.25
A31: 700 - 749 | B31: CRG-2 | C31: ='Repo rate'!$B$4 -> 5.25 | D31: 2.75 | E31: =C31+D31 -> 8 | F31: 0.1 | G31: -0.45 | H31: =E31+F31+G31 -> 7.65
A32: 650 - 699 | B32: CRG-3 | C32: ='Repo rate'!$B$4 -> 5.25 | D32: 2.75 | E32: =C32+D32 -> 8 | F32: 0.5 | G32: 0 | H32: =E32+F32+G32 -> 8.5
A33: < 650 | B33: CRG-4 | C33: ='Repo rate'!$B$4 -> 5.25 | D33: 2.75 | E33: =C33+D33 -> 8 | F33: 2 | G33: -0.1 | H33: =E33+F33+G33 -> 9.9
A35: Condition | B35: Loan amount above Rs. 100 lakhs - 250 lakhs
A36: 800+ | B36: CRG-prime | C36: ='Repo rate'!$B$4 -> 5.25 | D36: 2.75 | E36: =C36+D36 -> 8 | F36: 0.05 | G36: -0.85 | H36: =E36+F36+G36 -> 7.2
A37: 750 - 799 | B37: CRG-1 | C37: ='Repo rate'!$B$4 -> 5.25 | D37: 2.75 | E37: =C37+D37 -> 8 | F37: 0.05 | G37: -0.85 | H37: =E37+F37+G37 -> 7.2
A38: 700 - 749 | B38: CRG-2 | C38: ='Repo rate'!$B$4 -> 5.25 | D38: 2.75 | E38: =C38+D38 -> 8 | F38: 0.1 | G38: -0.5 | H38: =E38+F38+G38 -> 7.6
A39: 650 - 699 | B39: CRG-3 | C39: ='Repo rate'!$B$4 -> 5.25 | D39: 2.75 | E39: =C39+D39 -> 8 | F39: 0.5 | G39: 0 | H39: =E39+F39+G39 -> 8.5
A40: < 650 | B40: CRG-4 | C40: ='Repo rate'!$B$4 -> 5.25 | D40: 2.75 | E40: =C40+D40 -> 8 | F40: 2 | G40: -0.2 | H40: =E40+F40+G40 -> 9.8
A42: Condition | B42: Loan amount above Rs. 250 lakhs
A43: 800+ | B43: CRG-prime | C43: ='Repo rate'!$B$4 -> 5.25 | D43: 2.75 | E43: =C43+D43 -> 8 | F43: 0.05 | G43: -0.85 | H43: =E43+F43+G43 -> 7.2
A44: 750 - 799 | B44: CRG-1 | C44: ='Repo rate'!$B$4 -> 5.25 | D44: 2.75 | E44: =C44+D44 -> 8 | F44: 0.05 | G44: -0.85 | H44: =E44+F44+G44 -> 7.2
...

Sheet Indian Overseas Bank
A1: Bank | B1: Indian Overseas Bank
A2: Interest rate link | B2: https://www.iob.bank.in/en/Lending-Interest-Rates
A3: Credit score range given | B3: Yes
A4: Interest rates as per score | B4: Yes
A5: Gender split | B5: No
A6: Occupation split | B6: Yes
A7: Rate types | B7: Floating & Fixed
A8: Rate base | B8: Repo + Mark-up
A9: Special Govt. Employees | B9: Yes
A10: Loan Type - Term Loan | B10: Yes
A11: Loan Type - Overdraft | B11: No
A12: Top up | B12: Yes
A13: Rate varies by insurance | B13: No
A14: Updated as on | B14: 46217
A16: Scheme | B16: Subhagruha-Housing Loans
A17: Loan type | B17: Term loan
D19: Floating rate
D20: Repo Linked Lending Rate
B21: Repo Rate | C21: Markup | D21: Rate base | E21: Discount | F21: Final rate
A22: Occupation | B22: Salaried
A23: 800+ | B23: ='Repo rate'!$B$4 -> 5.25 | C23: 2.85 | D23: =B23+C23 -> 8.1 | E23: -0.9 | F23: =D23+E23 -> 7.2
A24: 775 - 799 | B24: ='Repo rate'!$B$4 -> 5.25 | C24: 2.85 | D24: =B24+C24 -> 8.1 | E24: -0.85 | F24: =D24+E24 -> 7.25
A25: 750 - 774 | B25: ='Repo rate'!$B$4 -> 5.25 | C25: 2.85 | D25: =B25+C25 -> 8.1 | E25: -0.55 | F25: =D25+E25 -> 7.55
A26: 725 - 749 | B26: ='Repo rate'!$B$4 -> 5.25 | C26: 2.85 | D26: =B26+C26 -> 8.1 | E26: -0.25 | F26: =D26+E26 -> 7.85
A27: 700 - 724 | B27: ='Repo rate'!$B$4 -> 5.25 | C27: 2.85 | D27: =B27+C27 -> 8.1 | E27: -0.15 | F27: =D27+E27 -> 7.95
A28: 680 - 699 | B28: ='Repo rate'!$B$4 -> 5.25 | C28: 2.85 | D28: =B28+C28 -> 8.1 | E28: 0.1 | F28: =D28+E28 -> 8.2
A29: -1 to 0 | B29: ='Repo rate'!$B$4 -> 5.25 | C29: 2.85 | D29: =B29+C29 -> 8.1 | E29: -0.25 | F29: =D29+E29 -> 7.85
A31: Occupation | B31: Self-Employed
A32: 800+ | B32: ='Repo rate'!$B$4 -> 5.25 | C32: 2.85 | D32: =B32+C32 -> 8.1 | E32: -0.8 | F32: =D32+E32 -> 7.3
A33: 775 - 799 | B33: ='Repo rate'!$B$4 -> 5.25 | C33: 2.85 | D33: =B33+C33 -> 8.1 | E33: -0.75 | F33: =D33+E33 -> 7.35
A34: 750 - 774 | B34: ='Repo rate'!$B$4 -> 5.25 | C34: 2.85 | D34: =B34+C34 -> 8.1 | E34: -0.45 | F34: =D34+E34 -> 7.65
A35: 725 - 749 | B35: ='Repo rate'!$B$4 -> 5.25 | C35: 2.85 | D35: =B35+C35 -> 8.1 | E35: -0.15 | F35: =D35+E35 -> 7.95
A36: 700 - 724 | B36: ='Repo rate'!$B$4 -> 5.25 | C36: 2.85 | D36: =B36+C36 -> 8.1 | E36: -0.05 | F36: =D36+E36 -> 8.05
A37: 680 - 699 | B37: ='Repo rate'!$B$4 -> 5.25 | C37: 2.85 | D37: =B37+C37 -> 8.1 | E37: 0.2 | F37: =D37+E37 -> 8.3
A38: -1 to 0 | B38: ='Repo rate'!$B$4 -> 5.25 | C38: 2.85 | D38: =B38+C38 -> 8.1 | E38: -0.15 | F38: =D38+E38 -> 7.95
A41: Scheme | B41: IOB HARIT SUBHAGRUHA (Green house)
A42: Loan type | B42: Term loan
D44: Floating rate
A45: Occupation | B45: Salaried
A46: 800+ | B46: ='Repo rate'!$B$4 -> 5.25 | C46: 2.85 | D46: =B46+C46 -> 8.1 | E46: -0.9 | F46: =D46+E46 -> 7.2
...

Sheet Punjab & Sind Bank
A1: Bank | B1: Punjab & Sind bank
A2: Interest rate link | B2: https://punjabandsind.bank.in/content/prlr
A3: Credit score range given | B3: Yes
A4: Interest rates as per score | B4: Yes
A5: Gender split | B5: No
A6: Occupation split | B6: Yes
A7: Rate types | B7: Floating
A8: Rate base | B8: Repo + Mark-up
A9: Special Govt. Employees | B9: Yes
A10: Loan Type - Term Loan | B10: Yes
A11: Loan Type - Overdraft | B11: No
A12: Top up | B12: Yes
A13: Rate varies by insurance | B13: No
A14: Updated as on | B14: 46249
A15: Scheme | B15: PSB Apna Ghar
A16: Loan type | B16: Term loan
A17: Floating rate
D18: External Benchmark Linked Lending Rate (EBLR)
B19: Repo Rate | C19: Markup | D19: Rate base | E19: Credit Risk Premium | F19: Strategic Business Premium | G19: Final rate
A21: Occupation | B21: Salaried & Self-Employed
A22: 825+ | B22: ='Repo rate'!$B$4 -> 5.25 | C22: 2.1 | D22: =B22+C22 -> 7.35 | E22: 0 | F22: 0 | G22: =D22+E22+F22 -> 7.35
A23: 791 - 824 | B23: ='Repo rate'!$B$4 -> 5.25 | C23: 2.1 | D23: =B23+C23 -> 7.35 | E23: 0.04 | F23: 0.01 | G23: =D23+E23+F23 -> 7.4
A24: 750 - 790 | B24: ='Repo rate'!$B$4 -> 5.25 | C24: 2.1 | D24: =B24+C24 -> 7.35 | E24: 0.16 | F24: 0.04 | G24: =D24+E24+F24 -> 7.55
A25: 725 - 749 | B25: ='Repo rate'!$B$4 -> 5.25 | C25: 2.1 | D25: =B25+C25 -> 7.35 | E25: 0.29 | F25: 0.26 | G25: =D25+E25+F25 -> 7.9
A26: 700 - 724 | B26: ='Repo rate'!$B$4 -> 5.25 | C26: 2.1 | D26: =B26+C26 -> 7.35 | E26: 0.46 | F26: 0.44 | G26: =D26+E26+F26 -> 8.25
A27: 650 - 699 | B27: ='Repo rate'!$B$4 -> 5.25 | C27: 2.1 | D27: =B27+C27 -> 7.35 | E27: 0.95 | F27: 0.75 | G27: =D27+E27+F27 -> 9.05 | H27: Only for renewal loans
A28: < = 649 | B28: ='Repo rate'!$B$4 -> 5.25 | C28: 2.1 | D28: =B28+C28 -> 7.35 | E28: 2.62 | F28: 0.73 | G28: =D28+E28+F28 -> 10.7 | H28: Only for renewal loans
A30: Scheme | B30: PSB Apna Ghar Sahaj & Apna Ghar Gaurav (fort govt. employees)
A31: Loan type | B31: Term loan
A33: Occupation | B33: Salaried
A34: 825+ | B34: ='Repo rate'!$B$4 -> 5.25 | C34: 2.1 | D34: =B34+C34 -> 7.35 | E34: 0 | F34: 0 | G34: =D34+E34+F34 -> 7.35
A35: 791 - 824 | B35: ='Repo rate'!$B$4 -> 5.25 | C35: 2.1 | D35: =B35+C35 -> 7.35 | E35: 0.04 | F35: 0.01 | G35: =D35+E35+F35 -> 7.4
A36: 750 - 790 | B36: ='Repo rate'!$B$4 -> 5.25 | C36: 2.1 | D36: =B36+C36 -> 7.35 | E36: 0.16 | F36: 0.04 | G36: =D36+E36+F36 -> 7.55
A37: 725 - 749 | B37: ='Repo rate'!$B$4 -> 5.25 | C37: 2.1 | D37: =B37+C37 -> 7.35 | E37: 0.29 | F37: 0.26 | G37: =D37+E37+F37 -> 7.9
A38: 700 - 724 | B38: ='Repo rate'!$B$4 -> 5.25 | C38: 2.1 | D38: =B38+C38 -> 7.35 | E38: 0.46 | F38: 0.44 | G38: =D38+E38+F38 -> 8.25
A39: 650 - 699 | B39: ='Repo rate'!$B$4 -> 5.25 | C39: 2.1 | D39: =B39+C39 -> 7.35 | E39: 0.95 | F39: 0.75 | G39: =D39+E39+F39 -> 9.05 | H39: Only for renewal loans
A40: < = 649 | B40: ='Repo rate'!$B$4 -> 5.25 | C40: 2.1 | D40: =B40+C40 -> 7.35 | E40: 2.62 | F40: 0.73 | G40: =D40+E40+F40 -> 10.7 | H40: Only for renewal loans
A43: Scheme | B43: PSB Apna Ghar Top Up
A44: Loan type | B44: Term loan
A46: Occupation | B46: Salaried & Self-Employed
...

Sheet State Bank of India
A1: Bank | B1: State Bank of India
A2: Interest rate link | B2: https://homeloans.sbi.bank.in/products/view/regular-home-loan
A3: Credit score range given | B3: Yes | C3: Check there excel file for old rates for cibil range ion wesbite
A4: Interest rates as per score | B4: Yes | C4: From internal executives file - Dilip
A5: Gender split | B5: No
A6: Occupation split | B6: Yes
A7: Rate types | B7: Floating
A8: Rate base | B8: Repo + Mark-up
A9: Special Govt. Employees | B9: Yes
A10: Loan Type - Term Loan | B10: Yes
A11: Loan Type - Overdraft | B11: Yes
A12: Top up | B12: Yes
A13: Rate varies by insurance | B13: No
A14: Updated as on | B14: 46217
A16: Scheme | B16: Home Loan
A17: Loan type | B17: Term loan
D18: Floating rate
D19: External Benchmark Lending Rate
B20: Repo Rate | C20: Markup | D20: Rate base | E20: Discount | F20: Final rate
B22: Salaried
A23: 825+ | B23: ='Repo rate'!$B$4 -> 5.25 | C23: 2.65 | D23: =B23+C23 -> 7.9 | E23: -0.65 | F23: =D23+E23 -> 7.25
A24: 780 - 824 | B24: ='Repo rate'!$B$4 -> 5.25 | C24: 2.65 | D24: =B24+C24 -> 7.9 | E24: -0.3 | F24: =D24+E24 -> 7.6
A25: 750 - 779 | B25: ='Repo rate'!$B$4 -> 5.25 | C25: 2.65 | D25: =B25+C25 -> 7.9 | E25: -0.2 | F25: =D25+E25 -> 7.7
A26: 700 - 749 | B26: ='Repo rate'!$B$4 -> 5.25 | C26: 2.65 | D26: =B26+C26 -> 7.9 | E26: -0.1 | F26: =D26+E26 -> 7.8
A27: 650 - 699 | B27: ='Repo rate'!$B$4 -> 5.25 | C27: 2.65 | D27: =B27+C27 -> 7.9 | E27: =0.35 -> 0.35 | F27: =D27+E27 -> 8.25
A28: 550 - 649 | B28: ='Repo rate'!$B$4 -> 5.25 | C28: 2.65 | D28: =B28+C28 -> 7.9 | E28: 0.65 | F28: =D28+E28 -> 8.55
A29: 151 - 200 | B29: ='Repo rate'!$B$4 -> 5.25 | C29: 2.65 | D29: =B29+C29 -> 7.9 | E29: 0.45 | F29: =D29+E29 -> 8.35
A30: 101 - 150 | B30: ='Repo rate'!$B$4 -> 5.25 | C30: 2.65 | D30: =B30+C30 -> 7.9 | E30: 0.45 | F30: =D30+E30 -> 8.35
A31: NTC | B31: ='Repo rate'!$B$4 -> 5.25 | C31: 2.65 | D31: =B31+C31 -> 7.9 | E31: 0 | F31: =D31+E31 -> 7.9
B33: Repo Rate | C33: Markup | D33: Repo Linked Lending Rate | E33: Discount | F33: Final rate
B34: A | C34: B | D34: D = A + B | F34: D + E
A35: Occupation | B35: Self-Employed
A36: 825+ | B36: ='Repo rate'!$B$4 -> 5.25 | C36: 2.65 | D36: =B36+C36 -> 7.9 | E36: -0.65 | F36: =D36+E36 -> 7.25
A37: 780 - 824 | B37: ='Repo rate'!$B$4 -> 5.25 | C37: 2.65 | D37: =B37+C37 -> 7.9 | E37: -0.2 | F37: =D37+E37 -> 7.7
A38: 750 - 779 | B38: ='Repo rate'!$B$4 -> 5.25 | C38: 2.65 | D38: =B38+C38 -> 7.9 | E38: -0.1 | F38: =D38+E38 -> 7.8
A39: 700 - 749 | B39: ='Repo rate'!$B$4 -> 5.25 | C39: 2.65 | D39: =B39+C39 -> 7.9 | E39: 0 | F39: =D39+E39 -> 7.9
A40: 650 - 699 | B40: ='Repo rate'!$B$4 -> 5.25 | C40: 2.65 | D40: =B40+C40 -> 7.9 | E40: =0.45 -> 0.45 | F40: =D40+E40 -> 8.35
A41: 550 - 649 | B41: ='Repo rate'!$B$4 -> 5.25 | C41: 2.65 | D41: =B41+C41 -> 7.9 | E41: 0.75 | F41: =D41+E41 -> 8.65
A42: 151 - 200 | B42: ='Repo rate'!$B$4 -> 5.25 | C42: 2.65 | D42: =B42+C42 -> 7.9 | E42: 0.55 | F42: =D42+E42 -> 8.45
A43: 101 - 150 | B43: ='Repo rate'!$B$4 -> 5.25 | C43: 2.65 | D43: =B43+C43 -> 7.9 | E43: 0.55 | F43: =D43+E43 -> 8.45
...

Sheet Bank of Maharashtra
A1: Bank | B1: Bank of Maharastra
A2: Interest rate link | B2: https://bankofmaharashtra.bank.in/retail-interest-rates
A3: Credit score range given | B3: Yes
A4: Interest rates as per score | B4: Yes
A5: Gender split | B5: Yes
A6: Occupation split | B6: Yes
A7: Rate types | B7: Floating & Fixed
A8: Rate base | B8: Repo + Mark-up
A9: Special Govt. Employees | B9: No | C9: Not included as only one slab
A10: Loan Type - Term Loan | B10: Yes
A11: Loan Type - Overdraft | B11: Yes
A12: Top up | B12: Yes
A13: Rate varies by insurance | B13: No
A14: Updated as on | B14: 46249
A16: Scheme | B16: Maha Super Housing Loan Scheme
A17: Loan type | B17: Term loan
D18: Floating rate
D19: Repo Linked Lending Rate
B20: Repo Rate | C20: Markup | D20: rate base | E20: Discount | F20: Final rate
A22: Occupation | B22: Salaried
A23: 800+ | B23: ='Repo rate'!$B$4 -> 5.25 | C23: 2.8 | D23: =B23+C23 -> 8.05 | E23: -1.05 | F23: =D23+E23 -> 7
A24: 750 - 799 | B24: ='Repo rate'!$B$4 -> 5.25 | C24: 2.8 | D24: =B24+C24 -> 8.05 | E24: -0.8 | F24: =D24+E24 -> 7.25
A25: 725 - 749 | B25: ='Repo rate'!$B$4 -> 5.25 | C25: 2.8 | D25: =B25+C25 -> 8.05 | E25: -0.35 | F25: =D25+E25 -> 7.7
A26: 700 - 724 | B26: ='Repo rate'!$B$4 -> 5.25 | C26: 2.8 | D26: =B26+C26 -> 8.05 | E26: -0.3 | F26: =D26+E26 -> 7.75
A27: 650 - 699 | B27: ='Repo rate'!$B$4 -> 5.25 | C27: 2.8 | D27: =B27+C27 -> 8.05 | E27: 0.3 | F27: =D27+E27 -> 8.35
A28: 600 - 649 | B28: ='Repo rate'!$B$4 -> 5.25 | C28: 2.8 | D28: =B28+C28 -> 8.05 | E28: 0.7 | F28: =D28+E28 -> 8.75
A29: < 600 | B29: ='Repo rate'!$B$4 -> 5.25 | C29: 2.8 | D29: =B29+C29 -> 8.05 | E29: 1.1 | F29: =D29+E29 -> 9.15
A30: NTC | B30: ='Repo rate'!$B$4 -> 5.25 | C30: 2.8 | D30: =B30+C30 -> 8.05 | E30: -0.35 | F30: =D30+E30 -> 7.7
A32: Occupation | B32: Self-Employed
A33: 800+ | B33: ='Repo rate'!$B$4 -> 5.25 | C33: 2.8 | D33: =B33+C33 -> 8.05 | E33: -0.95 | F33: =D33+E33 -> 7.1
A34: 750 - 799 | B34: ='Repo rate'!$B$4 -> 5.25 | C34: 2.8 | D34: =B34+C34 -> 8.05 | E34: -0.7 | F34: =D34+E34 -> 7.35
A35: 725 - 749 | B35: ='Repo rate'!$B$4 -> 5.25 | C35: 2.8 | D35: =B35+C35 -> 8.05 | E35: -0.25 | F35: =D35+E35 -> 7.8
A36: 700 - 724 | B36: ='Repo rate'!$B$4 -> 5.25 | C36: 2.8 | D36: =B36+C36 -> 8.05 | E36: -0.1 | F36: =D36+E36 -> 7.95
A37: 650 - 699 | B37: ='Repo rate'!$B$4 -> 5.25 | C37: 2.8 | D37: =B37+C37 -> 8.05 | E37: 0.5 | F37: =D37+E37 -> 8.55
A38: 600 - 649 | B38: ='Repo rate'!$B$4 -> 5.25 | C38: 2.8 | D38: =B38+C38 -> 8.05 | E38: 0.9 | F38: =D38+E38 -> 8.95
A39: < 600 | B39: ='Repo rate'!$B$4 -> 5.25 | C39: 2.8 | D39: =B39+C39 -> 8.05 | E39: 1.6 | F39: =D39+E39 -> 9.65
A40: NTC | B40: ='Repo rate'!$B$4 -> 5.25 | C40: 2.8 | D40: =B40+C40 -> 8.05 | E40: -0.15 | F40: =D40+E40 -> 7.9
A43: Scheme | B43: Maha Super Green Building (For green building)
A44: Loan type | B44: Term loan
A46: Occupation | B46: Salaried
...

Sheet UCO Bank
A1: Bank | B1: UCO Bank
A2: Interest rate link | B2: https://www.uco.bank.in/repo
A3: Credit score range given | B3: Yes
A4: Interest rates as per score | B4: Yes
A5: Gender split | B5: Yes
A6: Occupation split | B6: No
A7: Rate types | B7: Floating
A8: Rate base | B8: Repo + Mark-up
A9: Special Govt. Employees | B9: No
A10: Loan Type - Term Loan | B10: Yes
A11: Loan Type - Overdraft | B11: No
A12: Top up | B12: Yes
A13: Rate varies by insurance | B13: No
A14: Updated as on | B14: 46217
A17: Scheme | B17: UCO Home
A18: Loan type | B18: Term loan
D19: Floating rate
D21: Repo Linked Lending Rate
B22: Repo Rate | C22: Markup | D22: rate base | E22: Spread | F22: Startegic Discount | G22: Final rate
A25: 850+ | B25: ='Repo rate'!$B$4 -> 5.25 | C25: 2.8 | D25: =B25+C25 -> 8.05 | E25: 0.05 | F25: -0.95 | G25: =D25+F25+E25 -> 7.15
A26: 825 - 849 | B26: ='Repo rate'!$B$4 -> 5.25 | C26: 2.8 | D26: =B26+C26 -> 8.05 | E26: 0.15 | F26: -0.95 | G26: =D26+F26+E26 -> 7.25
A27: 800 - 824 | B27: ='Repo rate'!$B$4 -> 5.25 | C27: 2.8 | D27: =B27+C27 -> 8.05 | E27: 0.25 | F27: -0.95 | G27: =D27+F27+E27 -> 7.35
A28: 750 - 799 | B28: ='Repo rate'!$B$4 -> 5.25 | C28: 2.8 | D28: =B28+C28 -> 8.05 | E28: 0.45 | F28: -0.95 | G28: =D28+F28+E28 -> 7.55
A29: 700 - 749 | B29: ='Repo rate'!$B$4 -> 5.25 | C29: 2.8 | D29: =B29+C29 -> 8.05 | E29: 0.75 | F29: -0.95 | G29: =D29+F29+E29 -> 7.85
A30: 650 - 699 | B30: ='Repo rate'!$B$4 -> 5.25 | C30: 2.8 | D30: =B30+C30 -> 8.05 | E30: 0.8 | F30: 0 | G30: =D30+F30+E30 -> 8.85
A31: 600 - 649 | B31: ='Repo rate'!$B$4 -> 5.25 | C31: 2.8 | D31: =B31+C31 -> 8.05 | E31: 1.2 | F31: 0 | G31: =D31+F31+E31 -> 9.25
A32: 0-1 or <300 | B32: ='Repo rate'!$B$4 -> 5.25 | C32: 2.8 | D32: =B32+C32 -> 8.05 | E32: 0.3 | F32: 0 | G32: =D32+F32+E32 -> 8.35
A35: Scheme | B35: UCO Top Up Home Loan
A36: Loan type | B36: Term loan
A38: Occupation | B38: Salaried & Self-Employed
A39: 850+ | B39: ='Repo rate'!$B$4 -> 5.25 | C39: 2.8 | D39: =B39+C39 -> 8.05 | E39: 0.1 | F39: 0 | G39: =D39+F39+E39 -> 8.15
A40: 825 - 849 | B40: ='Repo rate'!$B$4 -> 5.25 | C40: 2.8 | D40: =B40+C40 -> 8.05 | E40: 0.45 | F40: 0 | G40: =D40+F40+E40 -> 8.5
A41: 800 - 824 | B41: ='Repo rate'!$B$4 -> 5.25 | C41: 2.8 | D41: =B41+C41 -> 8.05 | E41: 0.7 | F41: 0 | G41: =D41+F41+E41 -> 8.75
A42: 750 - 799 | B42: ='Repo rate'!$B$4 -> 5.25 | C42: 2.8 | D42: =B42+C42 -> 8.05 | E42: 1.05 | F42: 0 | G42: =D42+F42+E42 -> 9.1
A43: 700 - 749 | B43: ='Repo rate'!$B$4 -> 5.25 | C43: 2.8 | D43: =B43+C43 -> 8.05 | E43: 1.2 | F43: 0 | G43: =D43+F43+E43 -> 9.25
A44: 650 - 699 | B44: ='Repo rate'!$B$4 -> 5.25 | C44: 2.8 | D44: =B44+C44 -> 8.05 | E44: 2.7 | F44: 0 | G44: =D44+F44+E44 -> 10.75
A46: Notes for | B46: UCO Home
A47: Addl. Concession Women Borrower - 0.05
A48: Addl. Concession Takeover - 0.1

Sheet Jammu & Kashmir Bank
A1: Bank | B1: Jammu & Kashmir Bank
A2: Interest rate link | B2: https://jkb.bank.in/housing-loans
A3: Credit score range given | B3: Yes
A4: Interest rates as per score | B4: Yes
A5: Gender split | B5: No
A6: Occupation split | B6: No
A7: Rate types | B7: Floating
A8: Rate base | B8: Repo + Mark-up
A9: Special Govt. Employees | B9: No
A10: Loan Type - Term Loan | B10: Yes
A11: Loan Type - Overdraft | B11: No
A12: Top up | B12: No
A13: Rate varies by insurance | B13: No
A14: Updated as on | B14: 46217
A15: Scheme | B15: Housing Loan
A16: Loan type | B16: Term loan
A17: Floating rate
D18: Housing Loan Repo Linked Lending Rate (HLRLLR)
B19: Repo Rate | C19: Markup | D19: Rate base | E19: Discount | F19: Final rate
A21: Occupation | B21: Salaried & Self-Employed
A22: 750+ | B22: ='Repo rate'!$B$4 -> 5.25 | C22: 2.6 | D22: =B22+C22 -> 7.85 | E22: -0.35 | F22: =D22+E22 -> 7.5
A23: 726 - 749 | B23: ='Repo rate'!$B$4 -> 5.25 | C23: 2.6 | D23: =B23+C23 -> 7.85 | E23: -0.25 | F23: =D23+E23 -> 7.6
A24: 701 - 725 | B24: ='Repo rate'!$B$4 -> 5.25 | C24: 2.6 | D24: =B24+C24 -> 7.85 | E24: -0.15 | F24: =D24+E24 -> 7.7
A25: 675 - 700 | B25: ='Repo rate'!$B$4 -> 5.25 | C25: 2.6 | D25: =B25+C25 -> 7.85 | E25: 0.1 | F25: =D25+E25 -> 7.95
A26: < 675 | B26: ='Repo rate'!$B$4 -> 5.25 | C26: 2.6 | D26: =B26+C26 -> 7.85 | E26: 0.35 | F26: =D26+E26 -> 8.2

Sheet DCB Bank
A1: Bank | B1: DCB Bank
A2: Interest rate link | B2: https://www.dcb.bank.in/rates/lending-rates
A3: Credit score range given | B3: No
A4: Interest rates as per score | B4: No
A5: Gender split | B5: No
A6: Occupation split | B6: No
A7: Rate types | B7: Floating
A8: Rate base | B8: Repo + Mark-up
A9: Special Govt. Employees | B9: No
A10: Loan Type - Term Loan | B10: Yes
A11: Loan Type - Overdraft | B11: No
A12: Top up | B12: No
A13: Rate varies by insurance | B13: No
A14: Updated as on | B14: 46217
A16: Scheme | B16: Home Loan
A17: Loan type | B17: Term loan
D18: Floating rate
D19: Repo Linked Lending Rate (RLLR)
B20: Repo Rate | C20: Markup | D20: rate base | E20: Discount | F20: Final rate
A22: occupation | B22: Salaried & Self-Employed
A23: 800+ | B23: ='Repo rate'!$B$4 -> 5.25 | C23: 4.83 | D23: =B23+C23 -> 10.08 | E23: -0.33 | F23: =D23+E23 -> 9.75
A24: 750 - 799 | B24: ='Repo rate'!$B$4 -> 5.25 | C24: 4.83 | D24: =B24+C24 -> 10.08 | E24: -0.18 | F24: =D24+E24 -> 9.9
A25: 700 - 749 | B25: ='Repo rate'!$B$4 -> 5.25 | C25: 4.83 | D25: =B25+C25 -> 10.08 | E25: 0.07 | F25: =D25+E25 -> 10.15
A26: 650 - 699 | B26: ='Repo rate'!$B$4 -> 5.25 | C26: 4.83 | D26: =B26+C26 -> 10.08 | E26: 0.22 | F26: =D26+E26 -> 10.3
A27: 600 - 649 | B27: ='Repo rate'!$B$4 -> 5.25 | C27: 4.83 | D27: =B27+C27 -> 10.08 | E27: 0.45 | F27: =D27+E27 -> 10.53
A28: < 600 | B28: ='Repo rate'!$B$4 -> 5.25 | C28: 4.83 | D28: =B28+C28 -> 10.08 | E28: 0.57 | F28: =D28+E28 -> 10.65

Sheet Indian Bank
A1: Bank | B1: Indian Bank
A2: Interest rate link | B2: https://indianbank.bank.in/en/interest-rates-on-personal-segment-loan-products#!
A3: Credit score range given | B3: No
A4: Interest rates as per score | B4: No
A5: Gender split | B5: No
A6: Occupation split | B6: No
A7: Rate types | B7: Floating
A8: Rate base | B8: Repo + Mark-up
A9: Special Govt. Employees | B9: No
A10: Loan Type - Term Loan | B10: Yes
A11: Loan Type - Overdraft | B11: Yes
A12: Top up | B12: No
A13: Rate varies by insurance | B13: No
A14: Updated as on | B14: 46217
A17: Scheme | B17: IB Home Loan
A18: Loan type | B18: Term loan
D19: Floating rate
D20: External Benchmark Lending Rate
B21: Repo Rate | C21: Markup | D21: rate base | E21: Discount | F21: Final rate
A23: Occupation | B23: Salaried & Self-Employed
A24: 800+ | B24: ='Repo rate'!$B$4 -> 5.25 | C24: 2.7 | D24: =B24+C24 -> 7.95 | E24: -0.8 | F24: =D24+E24 -> 7.15
A25: 750 - 799 | B25: ='Repo rate'!$B$4 -> 5.25 | C25: 2.7 | D25: =B25+C25 -> 7.95 | E25: -0.5 | F25: =D25+E25 -> 7.45
A26: 700 - 749 | B26: ='Repo rate'!$B$4 -> 5.25 | C26: 2.7 | D26: =B26+C26 -> 7.95 | E26: -0.2 | F26: =D26+E26 -> 7.75
A27: 650 - 699 | B27: ='Repo rate'!$B$4 -> 5.25 | C27: 2.7 | D27: =B27+C27 -> 7.95 | E27: 0 | F27: =D27+E27 -> 7.95
A28: 600 - 649 | B28: ='Repo rate'!$B$4 -> 5.25 | C28: 2.7 | D28: =B28+C28 -> 7.95 | E28: 0.2 | F28: =D28+E28 -> 8.15
A29: < 600 | B29: ='Repo rate'!$B$4 -> 5.25 | C29: 2.7 | D29: =B29+C29 -> 7.95 | E29: 0.6 | F29: =D29+E29 -> 8.55
A32: Scheme | B32: IB Home Loan Flexi
A33: Loan type | B33: Overdraft
D34: Floating rate
A36: Occupation | B36: Salaried & Self-Employed
A37: 800+ | B37: ='Repo rate'!$B$4 -> 5.25 | C37: 2.7 | D37: =B37+C37 -> 7.95 | E37: -0.4 | F37: =D37+E37 -> 7.55
A38: 750 - 799 | B38: ='Repo rate'!$B$4 -> 5.25 | C38: 2.7 | D38: =B38+C38 -> 7.95 | E38: -0.1 | F38: =D38+E38 -> 7.85
A39: 700 - 749 | B39: ='Repo rate'!$B$4 -> 5.25 | C39: 2.7 | D39: =B39+C39 -> 7.95 | E39: 0.2 | F39: =D39+E39 -> 8.15
A40: 650 - 699 | B40: ='Repo rate'!$B$4 -> 5.25 | C40: 2.7 | D40: =B40+C40 -> 7.95 | E40: 0.4 | F40: =D40+E40 -> 8.35
A41: 600 - 649 | B41: ='Repo rate'!$B$4 -> 5.25 | C41: 2.7 | D41: =B41+C41 -> 7.95 | E41: 0.6 | F41: =D41+E41 -> 8.55
A42: < 600 | B42: ='Repo rate'!$B$4 -> 5.25 | C42: 2.7 | D42: =B42+C42 -> 7.95 | E42: 1 | F42: =D42+E42 -> 8.95

Sheet Bandhan Bank
A1: Bank | B1: Bandhan Bank
A2: Interest rate link | B2: https://bandhan.bank.in/personal/home-loan/suraksha#rctabtwo
A3: Credit score range given | B3: No
A4: Interest rates as per score | B4: No
A5: Gender split | B5: No
A6: Occupation split | B6: No
A7: Rate types | B7: Floating
A8: Rate base | B8: Repo
A9: Special Govt. Employees | B9: No
A10: Loan Type - Term Loan | B10: Yes
A11: Loan Type - Overdraft | B11: No
A12: Top up | B12: No
A13: Rate varies by insurance | B13: No
A14: Updated as on | B14: 46217
A16: Scheme | B16: Suraksha Home Loan
A17: Loan type | B17: Term loan
C18: Floating rate
B20: Repo Rate | C20: Markup | D20: Final rate
B21: Rate base
A22: Occupation | B22: Salaried & Self-Employed
A23: 800+ | B23: ='Repo rate'!$B$4 -> 5.25 | C23: 2.15 | D23: =B23+C23 -> 7.4
A24: 750 - 799 | B24: ='Repo rate'!$B$4 -> 5.25 | C24: 2.4 | D24: =B24+C24 -> 7.65
A25: 700 - 749 | B25: ='Repo rate'!$B$4 -> 5.25 | C25: 3 | D25: =B25+C25 -> 8.25
A26: 650 - 699 | B26: ='Repo rate'!$B$4 -> 5.25 | C26: 3.2 | D26: =B26+C26 -> 8.45
A27: 600 - 649 | B27: ='Repo rate'!$B$4 -> 5.25 | C27: 3.6 | D27: =B27+C27 -> 8.85
A28: < 600 | B28: ='Repo rate'!$B$4 -> 5.25 | C28: 4 | D28: =B28+C28 -> 9.25

Sheet City Union Bank
A1: Bank | B1: City Union Bank
A2: Interest rate link | B2: https://cityunionbank.bank.in/eblr-interest-rate
A3: Credit score range given | B3: No
A4: Interest rates as per score | B4: No
A5: Gender split | B5: No
A6: Occupation split | B6: No
A7: Rate types | B7: Floating
A8: Rate base | B8: Repo + Mark-up
A9: Special Govt. Employees | B9: No
A10: Loan Type - Term Loan | B10: Yes
A11: Loan Type - Overdraft | B11: No
A12: Top up | B12: No
... A15: Occupation | B15: Salaried & Self-Employed
A16: Floating rate
A19: Scheme | B19: affordable Home Loan
A20: Loan type | B20: Term loan
D21: External Benchmark Lending Rate
B22: Repo Rate | C22: Markup | D22: rate base | E22: Discount | F22: Final rate
A23: Condition
A24: Loan amount | B24: upto 30 lakhs
A25: 800+ | B25: ='Repo rate'!$B$4 -> 5.25 | C25: 4.45 | D25: =B25+C25 -> 9.7 | E25: -1.45 | F25: =D25+E25 -> 8.25
A26: 700 -799 | B26: ='Repo rate'!$B$4 -> 5.25 | C26: 4.45 | D26: =B26+C26 -> 9.7 | E26: -1.2 | F26: =D26+E26 -> 8.5
A27: 100 - 200 | B27: ='Repo rate'!$B$4 -> 5.25 | C27: 4.45 | D27: =B27+C27 -> 9.7 | E27: -0.7 | F27: =D27+E27 -> 9
A29: Scheme | B29: Prime Home Loan
A30: Loan type | B30: Term loan
D32: External Benchmark Lending Rate
B33: Repo Rate | C33: Markup | D33: rate base | E33: Discount | F33: Final rate
A34: Condition
A35: Loan amount | B35: 30 lakhs to 75 lakhs
A36: 800+ | B36: ='Repo rate'!$B$4 -> 5.25 | C36: 4.45 | D36: =B36+C36 -> 9.7 | E36: -1.2 | F36: =D36+E36 -> 8.5
A37: 700 -799 | B37: ='Repo rate'!$B$4 -> 5.25 | C37: 4.45 | D37: =B37+C37 -> 9.7 | E37: -0.95 | F37: =D37+E37 -> 8.75
A38: 100 - 200 | B38: ='Repo rate'!$B$4 -> 5.25 | C38: 4.45 | D38: =B38+C38 -> 9.7 | E38: -0.45 | F38: =D38+E38 -> 9.25
A40: Scheme | B40: Premium Home Loan
A41: Loan type | B41: Term loan
A42: Floating rate
D43: External Benchmark Lending Rate
B44: Repo Rate | C44: Markup | D44: rate base | E44: Discount | F44: Final rate
A45: Condition
A46: Loan amount | B46: 75 lakhs to 7.5 crore
A47: 800+ | B47: ='Repo rate'!$B$4 -> 5.25 | C47: 4.45 | D47: =B47+C47 -> 9.7 | E47: -0.95 | F47: =D47+E47 -> 8.75
...

Sheet Axis Bank
A1: Bank | B1: Axis bank
A2: Interest rate link | B2: https://www.axis.bank.in/loans/home-loan/interest-rates-charges#interest-rates
A3: Credit score range given | B3: No
A4: Interest rates as per score | B4: No
A5: Gender split | B5: No
A6: Occupation split | B6: No
A7: Rate types | B7: Floating
A8: Rate base | B8: Repo
A9: Special Govt. Employees | B9: No
A10: Loan Type - Term Loan | B10: Yes
A11: Loan Type - Overdraft | B11: Yes
A12: Top up | B12: No
A13: Rate varies by insurance | B13: No
A14: Updated as on | B14: 46217
A16: Scheme | B16: Home Loan
A17: Loan type | B17: Term loan
A18: Floating rate
B20: Repo Rate | C20: Markup | D20: Final rate
B21: Rate base
A22: Occupation | B22: Salaried & Self-Employed
A23: 800+ | B23: ='Repo rate'!$B$4 -> 5.25 | C23: 1.95 | D23: =B23+C23 -> 7.2
A24: 750 - 799 | B24: ='Repo rate'!$B$4 -> 5.25 | C24: 2.1 | D24: =B24+C24 -> 7.35
A25: 700 - 749 | B25: ='Repo rate'!$B$4 -> 5.25 | C25: 2.35 | D25: =B25+C25 -> 7.6
A26: 650 - 699 | B26: ='Repo rate'!$B$4 -> 5.25 | C26: 2.75 | D26: =B26+C26 -> 8
A27: 600 - 649 | B27: ='Repo rate'!$B$4 -> 5.25 | C27: 3.45 | D27: =B27+C27 -> 8.7
A28: < 600 | B28: ='Repo rate'!$B$4 -> 5.25 | C28: 3.8 | D28: =B28+C28 -> 9.05
A31: Scheme | B31: Supre Saver Home Loan
A32: Loan type | B32: Overdraft
C33: Floating rate
A34: Occupation | B34: Salaried & Self-Employed
A35: 800+ | B35: ='Repo rate'!$B$4 -> 5.25 | C35: 2.35 | D35: =B35+C35 -> 7.6
A36: 750 - 799 | B36: ='Repo rate'!$B$4 -> 5.25 | C36: 2.5 | D36: =B36+C36 -> 7.75
A37: 700 - 749 | B37: ='Repo rate'!$B$4 -> 5.25 | C37: 2.85 | D37: =B37+C37 -> 8.1
A38: 650 - 699 | B38: ='Repo rate'!$B$4 -> 5.25 | C38: 3.15 | D38: =B38+C38 -> 8.4
A39: 600 - 649 | B39: ='Repo rate'!$B$4 -> 5.25 | C39: 3.85 | D39: =B39+C39 -> 9.1
A40: < 600 | B40: ='Repo rate'!$B$4 -> 5.25 | C40: 4.2 | D40: =B40+C40 -> 9.45

Sheet ICICI Bank
A1: Bank | B1: ICICI Bank
A2: Interest rate link | B2: https://www.icici.bank.in/personal-banking/loans/home-loan/interest-rates?ITM=nli_homeLoan_loans_homeLoan_na_3_na_na_NLI
A3: Credit score range given | B3: No
A4: Interest rates as per score | B4: No
A5: Gender split | B5: No
A6: Occupation split | B6: No
A7: Rate types | B7: Floating
A8: Rate base | B8: Repo
A9: Special Govt. Employees | B9: No
A10: Loan Type - Term Loan | B10: Yes
A11: Loan Type - Overdraft | B11: Yes
A12: Top up | B12: No
A13: Rate varies by insurance | B13: No
A14: Updated as on | B14: 46217
A17: Scheme | B17: Home Loan
A18: Loan type | B18: Term loan
A19: Floating rate
B21: Repo Rate | C21: Markup | D21: Final rate
B22: rate base
A23: Occupation | B23: Salaried & Self-Employed
A24: 800+ | B24: ='Repo rate'!$B$4 -> 5.25 | C24: 1.9 | D24: =B24+C24 -> 7.15
A25: 750 - 799 | B25: ='Repo rate'!$B$4 -> 5.25 | C25: 2.4 | D25: =B25+C25 -> 7.65
A26: 700 - 749 | B26: ='Repo rate'!$B$4 -> 5.25 | C26: 2.55 | D26: =B26+C26 -> 7.8
A27: 650 - 699 | B27: ='Repo rate'!$B$4 -> 5.25 | C27: 2.85 | D27: =B27+C27 -> 8.1
A28: 600 - 649 | B28: ='Repo rate'!$B$4 -> 5.25 | C28: 3.25 | D28: =B28+C28 -> 8.5
A29: < 600 | B29: ='Repo rate'!$B$4 -> 5.25 | C29: 3.55 | D29: =B29+C29 -> 8.8
A32: Scheme | B32: ICICI Money Saver
A33: Loan type | B33: Overdraft
A34: Floating rate
A36: Occupation | B36: Salaried & Self-Employed
A37: 800+ | B37: ='Repo rate'!$B$4 -> 5.25 | C37: 2.15 | D37: =B37+C37 -> 7.4
A38: 750 - 799 | B38: ='Repo rate'!$B$4 -> 5.25 | C38: 2.65 | D38: =B38+C38 -> 7.9
A39: 700 - 749 | B39: ='Repo rate'!$B$4 -> 5.25 | C39: 2.75 | D39: =B39+C39 -> 8
A40: 650 - 699 | B40: ='Repo rate'!$B$4 -> 5.25 | C40: 3.25 | D40: =B40+C40 -> 8.5
A41: 600 - 649 | B41: ='Repo rate'!$B$4 -> 5.25 | C41: 3.75 | D41: =B41+C41 -> 9
A42: < 600 | B42: ='Repo rate'!$B$4 -> 5.25 | C42: 3.95 | D42: =B42+C42 -> 9.2

Sheet HDFC Bank
A1: Bank | B1: HDFC Bank
A2: Interest rate link | B2: https://www.hdfc.bank.in/home-loan/interest-rates-and-charges
A3: Credit score range given | B3: No
A4: Interest rates as per score | B4: No
A5: Gender split | B5: No
A6: Occupation split | B6: No
A7: Rate types | B7: Floating
A8: Rate base | B8: Repo
A9: Special Govt. Employees | B9: No
A10: Loan Type - Term Loan | B10: Yes
A11: Loan Type - Overdraft | B11: Yes
A12: Top up | B12: No
A13: Rate varies by insurance | B13: No
A14: Updated as on | B14: 46217
A18: Scheme | B18: Home Loan
A19: Loan type | B19: Term loan
A20: Floating rate
B22: Repo Rate | C22: Markup | D22: Final rate
B23: rate base
A24: Occupation | B24: Salaried & Self-Employed
A25: 800+ | B25: ='Repo rate'!$B$4 -> 5.25 | C25: 2 | D25: =B25+C25 -> 7.25
A26: 750 - 799 | B26: ='Repo rate'!$B$4 -> 5.25 | C26: 2.35 | D26: =B26+C26 -> 7.6
A27: 700 - 749 | B27: ='Repo rate'!$B$4 -> 5.25 | C27: 2.65 | D27: =B27+C27 -> 7.9
A28: 650 - 699 | B28: ='Repo rate'!$B$4 -> 5.25 | C28: 2.9 | D28: =B28+C28 -> 8.15
A29: 600 - 649 | B29: ='Repo rate'!$B$4 -> 5.25 | C29: 3.2 | D29: =B29+C29 -> 8.45
A30: < 600 | B30: ='Repo rate'!$B$4 -> 5.25 | C30: 3.4 | D30: =B30+C30 -> 8.65

Sheet Dhanlaxmi Bank
A1: Bank | B1: Dhanlaxmi Bank
A2: Interest rate link | B2: https://www.dhan.bank.in/interest-rates/
A3: Credit score range given | B3: Yes | C3: Only internal rating is given.
A4: Interest rates as per score | B4: Yes
A5: Gender split | B5: No
A6: Occupation split | B6: No
A7: Rate types | B7: Floating
A8: Rate base | B8: Repo
A9: Special Govt. Employees | B9: No
A10: Loan Type - Term Loan | B10: Yes
A11: Loan Type - Overdraft | B11: Yes
A12: Top up | B12: No
A13: Rate varies by insurance | B13: No
A14: Updated as on | B14: 46217
A16: Scheme | B16: Home Loan
A17: Loan type | B17: Term loan
A18: Floating rate
B20: Internal Rating | C20: Repo Rate | D20: Markup | E20: Final rate
C21: rate base
A22: Occupation | B22: Salaried & Self-Employed
A23: 825+ | B23: AAA | C23: ='Repo rate'!$B$4 -> 5.25 | D23: 2.95 | E23: =C23+D23 -> 8.2
A24: 800 - 824 | B24: AAA | C24: ='Repo rate'!$B$4 -> 5.25 | D24: 3.05 | E24: =C24+D24 -> 8.3
A25: 750 - 799 | B25: AAA | C25: ='Repo rate'!$B$4 -> 5.25 | D25: 3.15 | E25: =C25+D25 -> 8.4
A26: 700 - 749 | B26: BBB | C26: ='Repo rate'!$B$4 -> 5.25 | D26: 3.75 | E26: =C26+D26 -> 9
A27: 650 - 699 | B27: BBB | C27: ='Repo rate'!$B$4 -> 5.25 | D27: 5.55 | E27: =C27+D27 -> 10.8
A28: 600 - 649 | B28: BBB | C28: ='Repo rate'!$B$4 -> 5.25 | D28: 5.75 | E28: =C28+D28 -> 11
A29: < 600 | B29: C | C29: ='Repo rate'!$B$4 -> 5.25 | D29: 6.25 | E29: =C29+D29 -> 11.5

Sheet Federal Bank
A1: Bank | B1: Federal Bank
A2: Interest rate link | B2: https://www.federal.bank.in/retail-loans-interest-rates
A3: Credit score range given | B3: No
A4: Interest rates as per score | B4: No
A5: Gender split | B5: No
A6: Occupation split | B6: No
A7: Rate types | B7: Floating
A8: Rate base | B8: Repo
A9: Special Govt. Employees | B9: No
A10: Loan Type - Term Loan | B10: Yes
A11: Loan Type - Overdraft | B11: No
A12: Top up | B12: No
A13: Rate varies by insurance | B13: No
A14: Updated as on | B14: 46217
A15: Scheme | B15: Home Loan
A16: Loan type | B16: Term loan
A17: Floating rate
B19: Repo Rate | C19: Markup | D19: Final rate
B20: rate base
A22: Occupation | B22: Salaried & Self-Employed
A23: 800+ | B23: ='Repo rate'!$B$4 -> 5.25 | C23: 2.1 | D23: =B23+C23 -> 7.35
A24: 750 - 799 | B24: ='Repo rate'!$B$4 -> 5.25 | C24: 2.5 | D24: =B24+C24 -> 7.75
A25: 700 - 749 | B25: ='Repo rate'!$B$4 -> 5.25 | C25: 2.7 | D25: =B25+C25 -> 7.95
A26: 650 - 699 | B26: ='Repo rate'!$B$4 -> 5.25 | C26: 3 | D26: =B26+C26 -> 8.25
A27: 600 - 649 | B27: ='Repo rate'!$B$4 -> 5.25 | C27: 3.4 | D27: =B27+C27 -> 8.65
A28: < 600 | B28: ='Repo rate'!$B$4 -> 5.25 | C28: 3.75 | D28: =B28+C28 -> 9

Sheet IDBI Bank
A1: Bank | B1: IDBI Bank
A2: Interest rate link | B2: https://www.idbi.bank.in/interest-rates.aspx
A3: Credit score range given | B3: Yes | D3: See the march pic in pixel
A4: Interest rates as per score | B4: Yes
A5: Gender split | B5: No
A6: Occupation split | B6: No
A7: Rate types | B7: Floating
A8: Rate base | B8: Repo + Mark-up
A9: Special Govt. Employees | B9: No
A10: Loan Type - Term Loan | B10: Yes
A11: Loan Type - Overdraft | B11: Yes
A12: Top up | B12: No
A13: Rate varies by insurance | B13: No
A14: Updated as on | B14: 46217
A16: Scheme | B16: Plain Vanilla Home Loan
A17: Loan type | B17: Term loan
A18: Floating rate
B20: Repo Rate | C20: Markup | D20: RLLR | E20: Discount | F20: Final rate
A22: Occupation | B22: Salaried & Self-Employed
A23: 825+ | B23: ='Repo rate'!$B$4 -> 5.25 | C23: 2.9 | D23: =B23+C23 -> 8.15 | E23: -0.8 | F23: =D23+E23 -> 7.35
A24: 781 - 824 | B24: ='Repo rate'!$B$4 -> 5.25 | C24: 2.9 | D24: =B24+C24 -> 8.15 | E24: -0.45 | F24: =D24+E24 -> 7.7
A25: 761 - 780 | B25: ='Repo rate'!$B$4 -> 5.25 | C25: 2.9 | D25: =B25+C25 -> 8.15 | E25: -0.2 | F25: =D25+E25 -> 7.95
A26: 741 - 760 | B26: ='Repo rate'!$B$4 -> 5.25 | C26: 2.9 | D26: =B26+C26 -> 8.15 | E26: -0.1 | F26: =D26+E26 -> 8.05
A27: 721 - 740 | B27: ='Repo rate'!$B$4 -> 5.25 | C27: 2.9 | D27: =B27+C27 -> 8.15 | E27: 0.75 | F27: =D27+E27 -> 8.9
A28: 700 - 720 | B28: ='Repo rate'!$B$4 -> 5.25 | C28: 2.9 | D28: =B28+C28 -> 8.15 | E28: 1.3 | F28: =D28+E28 -> 9.45
A29: 650 - 699 | B29: ='Repo rate'!$B$4 -> 5.25 | C29: 2.9 | D29: =B29+C29 -> 8.15 | E29: 1.9 | F29: =D29+E29 -> 10.05
A31: Scheme | B31: Home Loan Ultra Saver
A32: Loan type | B32: Overdraft
A35: Occupation | B35: Salaried & Self-Employed
A36: 825+ | B36: ='Repo rate'!$B$4 -> 5.25 | C36: 2.9 | D36: =B36+C36 -> 8.15 | E36: -0.4 | F36: =D36+E36 -> 7.75
A37: 781 - 824 | B37: ='Repo rate'!$B$4 -> 5.25 | C37: 2.9 | D37: =B37+C37 -> 8.15 | E37: -0.05 | F37: =D37+E37 -> 8.1
A38: 761 - 780 | B38: ='Repo rate'!$B$4 -> 5.25 | C38: 2.9 | D38: =B38+C38 -> 8.15 | E38: 0.2 | F38: =D38+E38 -> 8.35
A39: 741 - 760 | B39: ='Repo rate'!$B$4 -> 5.25 | C39: 2.9 | D39: =B39+C39 -> 8.15 | E39: 0.3 | F39: =D39+E39 -> 8.45
A40: 721 - 740 | B40: ='Repo rate'!$B$4 -> 5.25 | C40: 2.9 | D40: =B40+C40 -> 8.15 | E40: 1.15 | F40: =D40+E40 -> 9.3
A41: 700 - 720 | B41: ='Repo rate'!$B$4 -> 5.25 | C41: 2.9 | D41: =B41+C41 -> 8.15 | E41: 1.7 | F41: =D41+E41 -> 9.85
A42: 650 - 699 | B42: ='Repo rate'!$B$4 -> 5.25 | C42: 2.9 | D42: =B42+C42 -> 8.15 | E42: 2.3 | F42: =D42+E42 -> 10.45
A45: Scheme | B45: Home loan Top Up
A46: Loan type | B46: Term loan
A49: Occupation | B49: Salaried & Self-Employed
A50: 825+ | B50: ='Repo rate'!$B$4 -> 5.25 | C50: 2.9 | D50: =B50+C50 -> 8.15 | E50: -0.6 | F50: =D50+E50 -> 7.55
...

Sheet IDFC First Bank
A1: Bank | B1: IDFC First Bank
A2: Interest rate link | B2: https://www.idfcfirst.bank.in/personal-banking/loans/home-loan/fees-and-charges
A3: Credit score range given | B3: No
A4: Interest rates as per score | B4: No
A5: Gender split | B5: No
A6: Occupation split | B6: No
A7: Rate types | B7: Floating
A8: Rate base | B8: Repo + Mark-up
A9: Special Govt. Employees | B9: No
A10: Loan Type - Term Loan | B10: Yes
A11: Loan Type - Overdraft | B11: No
A12: Top up | B12: No
A13: Rate varies by insurance | B13: No
A14: Updated as on | B14: 46217
A15: Scheme | B15: Home Loan
A16: Loan type | B16: Term loan
A17: Floating rate
D18: RLLR
B19: Repo Rate | C19: Markup | D19: rate base | E19: Discount | F19: Final rate
A21: Occupation | B21: Salaried & Self-Employed
A22: 800 + | B22: ='Repo rate'!$B$4 -> 5.25 | C22: 2 | D22: =B22+C22 -> 7.25 | E22: 0.5 | F22: =D22+E22 -> 7.75
A23: 750 - 799 | B23: ='Repo rate'!$B$4 -> 5.25 | C23: 2 | D23: =B23+C23 -> 7.25 | E23: 0.7 | F23: =D23+E23 -> 7.95
A24: 700 - 749 | B24: ='Repo rate'!$B$4 -> 5.25 | C24: 2 | D24: =B24+C24 -> 7.25 | E24: 0.9 | F24: =D24+E24 -> 8.15
A25: 650 - 699 | B25: ='Repo rate'!$B$4 -> 5.25 | C25: 2 | D25: =B25+C25 -> 7.25 | E25: 1.2 | F25: =D25+E25 -> 8.45
A26: 600 - 649 | B26: ='Repo rate'!$B$4 -> 5.25 | C26: 2 | D26: =B26+C26 -> 7.25 | E26: 1.35 | F26: =D26+E26 -> 8.6

Sheet Karur Vyasa Bank
A1: Bank | B1: Karur Vyasa Bank
A2: Interest rate link | B2: https://www.kvb.bank.in/interest-rates/
A3: Credit score range given | B3: No
A4: Interest rates as per score | B4: No
A5: Gender split | B5: No
A6: Occupation split | B6: No
A7: Rate types | B7: Floating
A8: Rate base | B8: Repo + Mark-up
A9: Special Govt. Employees | B9: No
A10: Loan Type - Term Loan | B10: Yes
A11: Loan Type - Overdraft | B11: No
A12: Top up | B12: No
A13: Rate varies by insurance | B13: No
A14: Updated as on | B14: 46217
A15: Scheme | B15: Housing Loan
A16: Loan type | B16: Term loan
A17: Floating rate
D18: RLLR
B19: Repo Rate | C19: Markup | D19: rate base | E19: Discount | F19: Final rate
A21: Occupation | B21: Salaried & Self-Employed
A22: 800 + | B22: ='Repo rate'!$B$4 -> 5.25 | C22: 3.3 | D22: =B22+C22 -> 8.55 | E22: -0.05 | F22: =D22+E22 -> 8.5
A23: 750 - 799 | B23: ='Repo rate'!$B$4 -> 5.25 | C23: 3.3 | D23: =B23+C23 -> 8.55 | E23: 0.2 | F23: =D23+E23 -> 8.75
A24: 700 - 749 | B24: ='Repo rate'!$B$4 -> 5.25 | C24: 3.3 | D24: =B24+C24 -> 8.55 | E24: 0.8 | F24: =D24+E24 -> 9.35
A25: 650 - 699 | B25: ='Repo rate'!$B$4 -> 5.25 | C25: 3.3 | D25: =B25+C25 -> 8.55 | E25: 1.6 | F25: =D25+E25 -> 10.15
A26: 600 - 649 | B26: ='Repo rate'!$B$4 -> 5.25 | C26: 3.3 | D26: =B26+C26 -> 8.55 | E26: 2.1 | F26: =D26+E26 -> 10.65
A28: Scheme | B28: Housing Loan Topup
A29: Loan type | B29: Term loan
A30: Floating rate
A32: Occupation | B32: Salaried & Self-Employed
A33: 800 + | B33: ='Repo rate'!$B$4 -> 5.25 | C33: 3.3 | D33: =B33+C33 -> 8.55 | E33: 0.2 | F33: =D33+E33 -> 8.75
A34: 750 - 799 | B34: ='Repo rate'!$B$4 -> 5.25 | C34: 3.3 | D34: =B34+C34 -> 8.55 | E34: 0.5 | F34: =D34+E34 -> 9.05
A35: 700 - 749 | B35: ='Repo rate'!$B$4 -> 5.25 | C35: 3.3 | D35: =B35+C35 -> 8.55 | E35: 1 | F35: =D35+E35 -> 9.55
A36: 650 - 699 | B36: ='Repo rate'!$B$4 -> 5.25 | C36: 3.3 | D36: =B36+C36 -> 8.55 | E36: 1.4 | F36: =D36+E36 -> 9.95
A37: 600 - 649 | B37: ='Repo rate'!$B$4 -> 5.25 | C37: 3.3 | D37: =B37+C37 -> 8.55 | E37: 1.7 | F37: =D37+E37 -> 10.25

Sheet Kotak Mahindra Bank
A1: Bank | B1: Kotak Mahindra Bank
A2: Interest rate link | B2: https://www.kotak.bank.in/en/personal-banking/loans/home-loan/interest-rates.html
A3: Credit score range given | B3: No
A4: Interest rates as per score | B4: No
A5: Gender split | B5: No
A6: Occupation split | B6: No
A7: Rate types | B7: Floating
A8: Rate base | B8: Repo
A9: Special Govt. Employees | B9: No
A10: Loan Type - Term Loan | B10: Yes
A11: Loan Type - Overdraft | B11: No
A12: Top up | B12: No
A13: Rate varies by insurance | B13: No
A14: Updated as on | B14: 46217
A15: Scheme | B15: Home Loan
A16: Loan type | B16: Term loan
A17: Floating rate
B19: Repo Rate | C19: Markup | D19: Final rate
B20: rate base
A21: Occupation | B21: Salaried & Self-Employed
A22: 800+ | B22: ='Repo rate'!$B$4 -> 5.25 | C22: 2.35 | D22: =B22+C22 -> 7.6
A23: 750 - 799 | B23: ='Repo rate'!$B$4 -> 5.25 | C23: 2.6 | D23: =B23+C23 -> 7.85
A24: 700 - 749 | B24: ='Repo rate'!$B$4 -> 5.25 | C24: 2.9 | D24: =B24+C24 -> 8.15
A25: 650 - 699 | B25: ='Repo rate'!$B$4 -> 5.25 | C25: 3.1 | D25: =B25+C25 -> 8.35
A26: 600 - 649 | B26: ='Repo rate'!$B$4 -> 5.25 | C26: 3.4 | D26: =B26+C26 -> 8.65
A27: < 600 | B27: ='Repo rate'!$B$4 -> 5.25 | C27: 3.6 | D27: =B27+C27 -> 8.85

Sheet Karnataka Bank
A1: Bank | B1: Karnataka Bank
A2: Interest rate link | B2: https://www.karnatakabank.bank.in/loan-interest-rates
A3: Credit score range given | B3: No
A4: Interest rates as per score | B4: No
A5: Gender split | B5: No
A6: Occupation split | B6: No
A7: Rate types | B7: Floating
A8: Rate base | B8: Repo
A9: Special Govt. Employees | B9: No
A10: Loan Type - Term Loan | B10: Yes
A11: Loan Type - Overdraft | B11: No
A12: Top up | B12: No
A13: Rate varies by insurance | B13: No
A14: Updated as on | B14: 46249
A15: Scheme | B15: KBL - Apna Ghar
A16: Loan type | B16: Term loan
A17: Floating rate
B19: Repo Rate | C19: Markup | D19: Final rate
B20: rate base
A21: Occupation | B21: Salaried & Self-Employed
A22: 800+ | B22: ='Repo rate'!$B$4 -> 5.25 | C22: 2.23 | D22: =B22+C22 -> 7.48
A23: 750 - 799 | B23: ='Repo rate'!$B$4 -> 5.25 | C23: 3 | D23: =B23+C23 -> 8.25
A24: 700 - 749 | B24: ='Repo rate'!$B$4 -> 5.25 | C24: 3.5 | D24: =B24+C24 -> 8.75
A25: 650 - 699 | B25: ='Repo rate'!$B$4 -> 5.25 | C25: 4.2 | D25: =B25+C25 -> 9.45
A26: 600 - 649 | B26: ='Repo rate'!$B$4 -> 5.25 | C26: 5.5 | D26: =B26+C26 -> 10.75
A27: < 600 | B27: ='Repo rate'!$B$4 -> 5.25 | C27: 6.55 | D27: =B27+C27 -> 11.8

Sheet RBL Bank
A1: Bank | B1: RBL Bank
A2: Interest rate link | B2: https://www.rbl.bank.in/personal-banking/loans/housing-loan?tabName=why-us
A3: Credit score range given | B3: No
A4: Interest rates as per score | B4: No
A5: Gender split | B5: No
A6: Occupation split | B6: No
A7: Rate types | B7: Floating
A8: Rate base | B8: Repo
A9: Special Govt. Employees | B9: No
A10: Loan Type - Term Loan | B10: Yes
A11: Loan Type - Overdraft | B11: No
A12: Top up | B12: No
A13: Rate varies by insurance | B13: No
A14: Updated as on | B14: 46217
A15: Scheme | B15: Housing Loan
A16: Loan type | B16: Term loan
A17: Floating rate
B19: Repo Rate | C19: Markup | D19: Final rate
B20: rate base
A21: Occupation | B21: Salaried & Self-Employed
A22: 800+ | B22: ='Repo rate'!$B$4 -> 5.25 | C22: 3.75 | D22: =B22+C22 -> 9
A23: 750 - 799 | B23: ='Repo rate'!$B$4 -> 5.25 | C23: 4.1 | D23: =B23+C23 -> 9.35
A24: 700 - 749 | B24: ='Repo rate'!$B$4 -> 5.25 | C24: 4.5 | D24: =B24+C24 -> 9.75
A25: 650 - 699 | B25: ='Repo rate'!$B$4 -> 5.25 | C25: 5 | D25: =B25+C25 -> 10.25
A26: 600 - 649 | B26: ='Repo rate'!$B$4 -> 5.25 | C26: 5.4 | D26: =B26+C26 -> 10.65
A27: < 600 | B27: ='Repo rate'!$B$4 -> 5.25 | C27: 6 | D27: =B27+C27 -> 11.25

